<?xml version="1.0" encoding="utf-8"?>
<!-- This URDF was automatically created by SolidWorks to URDF Exporter! Originally created by Stephen Brawner (brawner@gmail.com) 
     Commit Version: 1.6.0-4-g7f85cfe  Build Version: 1.6.7995.38578
     For more information, please see http://wiki.ros.org/sw_urdf_exporter -->
<robot
  name="mobile_base_assembly rigrig størrelse hjul">
  <link
    name="base_link">
    <inertial>
      <origin
        xyz="-0.0024750006390785 -0.185259399389036 -0.00158375241138109"
        rpy="0 0 0" />
      <mass
        value="7.12750649390085" />
      <inertia
        ixx="0.0457606455387283"
        ixy="2.77322922062716E-06"
        ixz="3.27411439344334E-05"
        iyy="0.0218108431317149"
        iyz="0.000878135124195841"
        izz="0.0543254750685279" />
    </inertial>
    <visual>
      <origin
        xyz="0 0 0"
        rpy="0 0 0" />
      <geometry>
        <mesh
          filename="package://mobile_base_assembly rigrig størrelse hjul/meshes/base_link.STL" />
      </geometry>
      <material
        name="">
        <color
          rgba="0 0 0 1" />
      </material>
    </visual>
    <collision>
      <origin
        xyz="0 0 0"
        rpy="0 0 0" />
      <geometry>
        <mesh
          filename="package://mobile_base_assembly rigrig størrelse hjul/meshes/base_link.STL" />
      </geometry>
    </collision>
  </link>
  <link
    name="left_wheel">
    <inertial>
      <origin
        xyz="4.16333634234434E-17 5.55111512312578E-17 0.0425"
        rpy="0 0 0" />
      <mass
        value="4.46342151734513" />
      <inertia
        ixx="0.0214375253295535"
        ixy="-9.27083006375532E-19"
        ixz="-7.97975622392489E-20"
        iyy="0.0214375253295535"
        iyz="-1.43995601033231E-20"
        izz="0.0375707416693319" />
    </inertial>
    <visual>
      <origin
        xyz="0 0 0"
        rpy="0 0 0" />
      <geometry>
        <mesh
          filename="package://mobile_base_assembly rigrig størrelse hjul/meshes/left_wheel.STL" />
      </geometry>
      <material
        name="">
        <color
          rgba="0.792156862745098 0.819607843137255 0.933333333333333 1" />
      </material>
    </visual>
    <collision>
      <origin
        xyz="0 0 0"
        rpy="0 0 0" />
      <geometry>
        <mesh
          filename="package://mobile_base_assembly rigrig størrelse hjul/meshes/left_wheel.STL" />
      </geometry>
    </collision>
  </link>
  <joint
    name="left_wheel_joint"
    type="continuous">
    <origin
      xyz="-0.1795 0 0"
      rpy="1.5708 0 1.5708" />
    <parent
      link="base_link" />
    <child
      link="left_wheel" />
    <axis
      xyz="0 0 1" />
  </joint>
  <link
    name="right_wheel">
    <inertial>
      <origin
        xyz="2.77555756156289E-17 0 -0.0425"
        rpy="0 0 0" />
      <mass
        value="4.46342151734513" />
      <inertia
        ixx="0.0214375253295535"
        ixy="-2.9042607713123E-19"
        ixz="-5.26009852170224E-19"
        iyy="0.0214375253295535"
        iyz="5.9105590148048E-20"
        izz="0.0375707416693319" />
    </inertial>
    <visual>
      <origin
        xyz="0 0 0"
        rpy="0 0 0" />
      <geometry>
        <mesh
          filename="package://mobile_base_assembly rigrig størrelse hjul/meshes/right_wheel.STL" />
      </geometry>
      <material
        name="">
        <color
          rgba="0.792156862745098 0.819607843137255 0.933333333333333 1" />
      </material>
    </visual>
    <collision>
      <origin
        xyz="0 0 0"
        rpy="0 0 0" />
      <geometry>
        <mesh
          filename="package://mobile_base_assembly rigrig størrelse hjul/meshes/right_wheel.STL" />
      </geometry>
    </collision>
  </link>
  <joint
    name="right_wheel_joint"
    type="continuous">
    <origin
      xyz="0.1745 0 0"
      rpy="1.5708 0 1.5708" />
    <parent
      link="base_link" />
    <child
      link="right_wheel" />
    <axis
      xyz="0 0 1" />
  </joint>
  <link
    name="camera">
    <inertial>
      <origin
        xyz="-0.00631546894314867 -0.00352733962572555 -0.04107698948983"
        rpy="0 0 0" />
      <mass
        value="0.434157647540387" />
      <inertia
        ixx="0.000312761614793385"
        ixy="-3.35388002099955E-08"
        ixz="-1.13015682548285E-05"
        iyy="0.00052582752815235"
        iyz="-1.47821574419058E-05"
        izz="0.000675087917784274" />
    </inertial>
    <visual>
      <origin
        xyz="0 0 0"
        rpy="0 0 0" />
      <geometry>
        <mesh
          filename="package://mobile_base_assembly rigrig størrelse hjul/meshes/camera.STL" />
      </geometry>
      <material
        name="">
        <color
          rgba="0.792156862745098 0.819607843137255 0.933333333333333 1" />
      </material>
    </visual>
    <collision>
      <origin
        xyz="0 0 0"
        rpy="0 0 0" />
      <geometry>
        <mesh
          filename="package://mobile_base_assembly rigrig størrelse hjul/meshes/camera.STL" />
      </geometry>
    </collision>
  </link>
  <joint
    name="camera_joint"
    type="fixed">
    <origin
      xyz="-0.0022996 0.27022 0.04328"
      rpy="2.3562 0 -3.1415" />
    <parent
      link="base_link" />
    <child
      link="camera" />
    <axis
      xyz="0 0 0" />
  </joint>
  <link
    name="laser">
    <inertial>
      <origin
        xyz="-3.24297391453392E-05 0.0304099645493233 -0.00053784996415665"
        rpy="0 0 0" />
      <mass
        value="0.77572976548165" />
      <inertia
        ixx="0.000937718836199801"
        ixy="3.8008877922495E-07"
        ixz="1.32636836288947E-06"
        iyy="0.000971728129760081"
        iyz="-1.59543715912E-06"
        izz="0.000813219708306808" />
    </inertial>
    <visual>
      <origin
        xyz="0 0 0"
        rpy="0 0 0" />
      <geometry>
        <mesh
          filename="package://mobile_base_assembly rigrig størrelse hjul/meshes/laser.STL" />
      </geometry>
      <material
        name="">
        <color
          rgba="0.792156862745098 0.819607843137255 0.933333333333333 1" />
      </material>
    </visual>
    <collision>
      <origin
        xyz="0 0 0"
        rpy="0 0 0" />
      <geometry>
        <mesh
          filename="package://mobile_base_assembly rigrig størrelse hjul/meshes/laser.STL" />
      </geometry>
    </collision>
  </link>
  <joint
    name="laser_joint"
    type="fixed">
    <origin
      xyz="-0.0024966 0.13302 -0.025212"
      rpy="1.5708 0 3.1416" />
    <parent
      link="base_link" />
    <child
      link="laser" />
    <axis
      xyz="0 0 0" />
  </joint>
</robot>